[2022-12-27 20:57:34,116] {taskinstance.py:1159} INFO - Dependencies all met for <TaskInstance: parking_pipeline.transform_data manual__2022-12-27T20:57:30.236945+00:00 [queued]>
[2022-12-27 20:57:34,123] {taskinstance.py:1159} INFO - Dependencies all met for <TaskInstance: parking_pipeline.transform_data manual__2022-12-27T20:57:30.236945+00:00 [queued]>
[2022-12-27 20:57:34,124] {taskinstance.py:1356} INFO - 
--------------------------------------------------------------------------------
[2022-12-27 20:57:34,124] {taskinstance.py:1357} INFO - Starting attempt 1 of 2
[2022-12-27 20:57:34,125] {taskinstance.py:1358} INFO - 
--------------------------------------------------------------------------------
[2022-12-27 20:57:34,135] {taskinstance.py:1377} INFO - Executing <Task(PythonOperator): transform_data> on 2022-12-27 20:57:30.236945+00:00
[2022-12-27 20:57:34,139] {standard_task_runner.py:52} INFO - Started process 8107 to run task
[2022-12-27 20:57:34,144] {standard_task_runner.py:79} INFO - Running: ['***', 'tasks', 'run', 'parking_pipeline', 'transform_data', 'manual__2022-12-27T20:57:30.236945+00:00', '--job-id', '348', '--raw', '--subdir', 'DAGS_FOLDER/parking_dag.py', '--cfg-path', '/tmp/tmpp_gvbrji', '--error-file', '/tmp/tmp_0eyukpn']
[2022-12-27 20:57:34,145] {standard_task_runner.py:80} INFO - Job 348: Subtask transform_data
[2022-12-27 20:57:34,199] {task_command.py:369} INFO - Running <TaskInstance: parking_pipeline.transform_data manual__2022-12-27T20:57:30.236945+00:00 [running]> on host 8fbeee8d3d5a
[2022-12-27 20:57:34,260] {taskinstance.py:1571} INFO - Exporting the following env vars:
AIRFLOW_CTX_DAG_OWNER=Airflow
AIRFLOW_CTX_DAG_ID=parking_pipeline
AIRFLOW_CTX_TASK_ID=transform_data
AIRFLOW_CTX_EXECUTION_DATE=2022-12-27T20:57:30.236945+00:00
AIRFLOW_CTX_TRY_NUMBER=1
AIRFLOW_CTX_DAG_RUN_ID=manual__2022-12-27T20:57:30.236945+00:00
[2022-12-27 20:57:34,276] {taskinstance.py:1889} ERROR - Task failed with exception
Traceback (most recent call last):
  File "/home/airflow/.local/lib/python3.7/site-packages/airflow/operators/python.py", line 171, in execute
    return_value = self.execute_callable()
  File "/home/airflow/.local/lib/python3.7/site-packages/airflow/operators/python.py", line 189, in execute_callable
    return self.python_callable(*self.op_args, **self.op_kwargs)
  File "/opt/airflow/dags/parking_dag.py", line 38, in _transform_parking_data
    df = df.set_index("parkingTransactionKey")
  File "/home/airflow/.local/lib/python3.7/site-packages/pandas/util/_decorators.py", line 311, in wrapper
    return func(*args, **kwargs)
  File "/home/airflow/.local/lib/python3.7/site-packages/pandas/core/frame.py", line 5451, in set_index
    raise KeyError(f"None of {missing} are in the columns")
KeyError: "None of ['parkingTransactionKey'] are in the columns"
[2022-12-27 20:57:34,289] {taskinstance.py:1400} INFO - Marking task as UP_FOR_RETRY. dag_id=parking_pipeline, task_id=transform_data, execution_date=20221227T205730, start_date=20221227T205734, end_date=20221227T205734
[2022-12-27 20:57:34,296] {standard_task_runner.py:97} ERROR - Failed to execute job 348 for task transform_data ("None of ['parkingTransactionKey'] are in the columns"; 8107)
[2022-12-27 20:57:34,317] {local_task_job.py:156} INFO - Task exited with return code 1
[2022-12-27 20:57:34,346] {local_task_job.py:273} INFO - 0 downstream tasks scheduled from follow-on schedule check
