[2022-12-27 20:51:24,456] {taskinstance.py:1159} INFO - Dependencies all met for <TaskInstance: parking_pipeline.transform_data scheduled__2022-12-27T20:49:19.958052+00:00 [queued]>
[2022-12-27 20:51:24,464] {taskinstance.py:1159} INFO - Dependencies all met for <TaskInstance: parking_pipeline.transform_data scheduled__2022-12-27T20:49:19.958052+00:00 [queued]>
[2022-12-27 20:51:24,465] {taskinstance.py:1356} INFO - 
--------------------------------------------------------------------------------
[2022-12-27 20:51:24,466] {taskinstance.py:1357} INFO - Starting attempt 1 of 2
[2022-12-27 20:51:24,467] {taskinstance.py:1358} INFO - 
--------------------------------------------------------------------------------
[2022-12-27 20:51:24,477] {taskinstance.py:1377} INFO - Executing <Task(PythonOperator): transform_data> on 2022-12-27 20:49:19.958052+00:00
[2022-12-27 20:51:24,482] {standard_task_runner.py:52} INFO - Started process 7658 to run task
[2022-12-27 20:51:24,488] {standard_task_runner.py:79} INFO - Running: ['***', 'tasks', 'run', 'parking_pipeline', 'transform_data', 'scheduled__2022-12-27T20:49:19.958052+00:00', '--job-id', '297', '--raw', '--subdir', 'DAGS_FOLDER/parking_dag.py', '--cfg-path', '/tmp/tmp0iw3xpf6', '--error-file', '/tmp/tmpdugfi152']
[2022-12-27 20:51:24,490] {standard_task_runner.py:80} INFO - Job 297: Subtask transform_data
[2022-12-27 20:51:24,546] {task_command.py:369} INFO - Running <TaskInstance: parking_pipeline.transform_data scheduled__2022-12-27T20:49:19.958052+00:00 [running]> on host 8fbeee8d3d5a
[2022-12-27 20:51:24,612] {taskinstance.py:1571} INFO - Exporting the following env vars:
AIRFLOW_CTX_DAG_OWNER=Airflow
AIRFLOW_CTX_DAG_ID=parking_pipeline
AIRFLOW_CTX_TASK_ID=transform_data
AIRFLOW_CTX_EXECUTION_DATE=2022-12-27T20:49:19.958052+00:00
AIRFLOW_CTX_TRY_NUMBER=1
AIRFLOW_CTX_DAG_RUN_ID=scheduled__2022-12-27T20:49:19.958052+00:00
[2022-12-27 20:51:24,626] {taskinstance.py:1889} ERROR - Task failed with exception
Traceback (most recent call last):
  File "/home/airflow/.local/lib/python3.7/site-packages/airflow/operators/python.py", line 171, in execute
    return_value = self.execute_callable()
  File "/home/airflow/.local/lib/python3.7/site-packages/airflow/operators/python.py", line 189, in execute_callable
    return self.python_callable(*self.op_args, **self.op_kwargs)
  File "/opt/airflow/dags/parking_dag.py", line 36, in _transform_parking_data
    print(data.keys())
AttributeError: 'str' object has no attribute 'keys'
[2022-12-27 20:51:24,638] {taskinstance.py:1400} INFO - Marking task as UP_FOR_RETRY. dag_id=parking_pipeline, task_id=transform_data, execution_date=20221227T204919, start_date=20221227T205124, end_date=20221227T205124
[2022-12-27 20:51:24,647] {standard_task_runner.py:97} ERROR - Failed to execute job 297 for task transform_data ('str' object has no attribute 'keys'; 7658)
[2022-12-27 20:51:24,660] {local_task_job.py:156} INFO - Task exited with return code 1
[2022-12-27 20:51:24,691] {local_task_job.py:273} INFO - 0 downstream tasks scheduled from follow-on schedule check
