[2022-12-27 21:45:24,738] {taskinstance.py:1159} INFO - Dependencies all met for <TaskInstance: parking_pipeline.transform_data scheduled__2022-12-27T21:43:21.176519+00:00 [queued]>
[2022-12-27 21:45:24,744] {taskinstance.py:1159} INFO - Dependencies all met for <TaskInstance: parking_pipeline.transform_data scheduled__2022-12-27T21:43:21.176519+00:00 [queued]>
[2022-12-27 21:45:24,745] {taskinstance.py:1356} INFO - 
--------------------------------------------------------------------------------
[2022-12-27 21:45:24,745] {taskinstance.py:1357} INFO - Starting attempt 1 of 2
[2022-12-27 21:45:24,746] {taskinstance.py:1358} INFO - 
--------------------------------------------------------------------------------
[2022-12-27 21:45:24,755] {taskinstance.py:1377} INFO - Executing <Task(PythonOperator): transform_data> on 2022-12-27 21:43:21.176519+00:00
[2022-12-27 21:45:24,759] {standard_task_runner.py:52} INFO - Started process 10123 to run task
[2022-12-27 21:45:24,763] {standard_task_runner.py:79} INFO - Running: ['***', 'tasks', 'run', 'parking_pipeline', 'transform_data', 'scheduled__2022-12-27T21:43:21.176519+00:00', '--job-id', '533', '--raw', '--subdir', 'DAGS_FOLDER/parking_dag.py', '--cfg-path', '/tmp/tmp58kxhs3c', '--error-file', '/tmp/tmp86p2c5z8']
[2022-12-27 21:45:24,764] {standard_task_runner.py:80} INFO - Job 533: Subtask transform_data
[2022-12-27 21:45:24,813] {task_command.py:369} INFO - Running <TaskInstance: parking_pipeline.transform_data scheduled__2022-12-27T21:43:21.176519+00:00 [running]> on host 8fbeee8d3d5a
[2022-12-27 21:45:24,870] {taskinstance.py:1571} INFO - Exporting the following env vars:
AIRFLOW_CTX_DAG_OWNER=Airflow
AIRFLOW_CTX_DAG_ID=parking_pipeline
AIRFLOW_CTX_TASK_ID=transform_data
AIRFLOW_CTX_EXECUTION_DATE=2022-12-27T21:43:21.176519+00:00
AIRFLOW_CTX_TRY_NUMBER=1
AIRFLOW_CTX_DAG_RUN_ID=scheduled__2022-12-27T21:43:21.176519+00:00
[2022-12-27 21:45:24,887] {taskinstance.py:1889} ERROR - Task failed with exception
Traceback (most recent call last):
  File "/home/airflow/.local/lib/python3.7/site-packages/airflow/operators/python.py", line 171, in execute
    return_value = self.execute_callable()
  File "/home/airflow/.local/lib/python3.7/site-packages/airflow/operators/python.py", line 189, in execute_callable
    return self.python_callable(*self.op_args, **self.op_kwargs)
  File "/opt/airflow/dags/parking_dag.py", line 39, in _transform_parking_data
    df = df.set_index(1)
  File "/home/airflow/.local/lib/python3.7/site-packages/pandas/util/_decorators.py", line 311, in wrapper
    return func(*args, **kwargs)
  File "/home/airflow/.local/lib/python3.7/site-packages/pandas/core/frame.py", line 5451, in set_index
    raise KeyError(f"None of {missing} are in the columns")
KeyError: 'None of [1] are in the columns'
[2022-12-27 21:45:24,900] {taskinstance.py:1400} INFO - Marking task as UP_FOR_RETRY. dag_id=parking_pipeline, task_id=transform_data, execution_date=20221227T214321, start_date=20221227T214524, end_date=20221227T214524
[2022-12-27 21:45:24,907] {standard_task_runner.py:97} ERROR - Failed to execute job 533 for task transform_data ('None of [1] are in the columns'; 10123)
[2022-12-27 21:45:24,935] {local_task_job.py:156} INFO - Task exited with return code 1
[2022-12-27 21:45:24,964] {local_task_job.py:273} INFO - 0 downstream tasks scheduled from follow-on schedule check
