[2022-12-23 22:49:33,144] {taskinstance.py:1159} INFO - Dependencies all met for <TaskInstance: parking_pipeline.is_api_available scheduled__2022-12-23T22:47:32.224493+00:00 [queued]>
[2022-12-23 22:49:33,151] {taskinstance.py:1159} INFO - Dependencies all met for <TaskInstance: parking_pipeline.is_api_available scheduled__2022-12-23T22:47:32.224493+00:00 [queued]>
[2022-12-23 22:49:33,152] {taskinstance.py:1356} INFO - 
--------------------------------------------------------------------------------
[2022-12-23 22:49:33,152] {taskinstance.py:1357} INFO - Starting attempt 1 of 2
[2022-12-23 22:49:33,153] {taskinstance.py:1358} INFO - 
--------------------------------------------------------------------------------
[2022-12-23 22:49:33,164] {taskinstance.py:1377} INFO - Executing <Task(HttpSensor): is_api_available> on 2022-12-23 22:47:32.224493+00:00
[2022-12-23 22:49:33,171] {standard_task_runner.py:52} INFO - Started process 3290 to run task
[2022-12-23 22:49:33,184] {standard_task_runner.py:79} INFO - Running: ['***', 'tasks', 'run', 'parking_pipeline', 'is_api_available', 'scheduled__2022-12-23T22:47:32.224493+00:00', '--job-id', '4', '--raw', '--subdir', 'DAGS_FOLDER/parking_dag.py', '--cfg-path', '/tmp/tmp_lz0jqt5', '--error-file', '/tmp/tmpmgk3n71n']
[2022-12-23 22:49:33,191] {standard_task_runner.py:80} INFO - Job 4: Subtask is_api_available
[2022-12-23 22:49:33,264] {task_command.py:369} INFO - Running <TaskInstance: parking_pipeline.is_api_available scheduled__2022-12-23T22:47:32.224493+00:00 [running]> on host 7b9b4435e086
[2022-12-23 22:49:33,326] {taskinstance.py:1571} INFO - Exporting the following env vars:
AIRFLOW_CTX_DAG_OWNER=Airflow
AIRFLOW_CTX_DAG_ID=parking_pipeline
AIRFLOW_CTX_TASK_ID=is_api_available
AIRFLOW_CTX_EXECUTION_DATE=2022-12-23T22:47:32.224493+00:00
AIRFLOW_CTX_TRY_NUMBER=1
AIRFLOW_CTX_DAG_RUN_ID=scheduled__2022-12-23T22:47:32.224493+00:00
[2022-12-23 22:49:33,327] {http.py:97} INFO - Poking: 
[2022-12-23 22:49:33,350] {taskinstance.py:1889} ERROR - Task failed with exception
Traceback (most recent call last):
  File "/home/airflow/.local/lib/python3.7/site-packages/airflow/sensors/base.py", line 277, in execute
    poke_return = self.poke(context)
  File "/home/airflow/.local/lib/python3.7/site-packages/airflow/providers/http/sensors/http.py", line 112, in poke
    raise exc
  File "/home/airflow/.local/lib/python3.7/site-packages/airflow/providers/http/sensors/http.py", line 103, in poke
    extra_options=self.extra_options,
  File "/home/airflow/.local/lib/python3.7/site-packages/airflow/providers/http/hooks/http.py", line 114, in run
    session = self.get_conn(headers)
  File "/home/airflow/.local/lib/python3.7/site-packages/airflow/providers/http/hooks/http.py", line 68, in get_conn
    conn = self.get_connection(self.http_conn_id)
  File "/home/airflow/.local/lib/python3.7/site-packages/airflow/hooks/base.py", line 67, in get_connection
    conn = Connection.get_connection_from_secrets(conn_id)
  File "/home/airflow/.local/lib/python3.7/site-packages/airflow/models/connection.py", line 430, in get_connection_from_secrets
    raise AirflowNotFoundException(f"The conn_id `{conn_id}` isn't defined")
airflow.exceptions.AirflowNotFoundException: The conn_id `is_api_available` isn't defined
[2022-12-23 22:49:33,354] {taskinstance.py:1400} INFO - Marking task as UP_FOR_RETRY. dag_id=parking_pipeline, task_id=is_api_available, execution_date=20221223T224732, start_date=20221223T224933, end_date=20221223T224933
[2022-12-23 22:49:33,362] {standard_task_runner.py:97} ERROR - Failed to execute job 4 for task is_api_available (The conn_id `is_api_available` isn't defined; 3290)
[2022-12-23 22:49:33,397] {local_task_job.py:156} INFO - Task exited with return code 1
[2022-12-23 22:49:33,433] {local_task_job.py:273} INFO - 0 downstream tasks scheduled from follow-on schedule check
