[2022-12-27 20:49:19,599] {taskinstance.py:1159} INFO - Dependencies all met for <TaskInstance: parking_pipeline.transform_data scheduled__2022-12-27T20:42:14.349080+00:00 [queued]>
[2022-12-27 20:49:19,608] {taskinstance.py:1159} INFO - Dependencies all met for <TaskInstance: parking_pipeline.transform_data scheduled__2022-12-27T20:42:14.349080+00:00 [queued]>
[2022-12-27 20:49:19,608] {taskinstance.py:1356} INFO - 
--------------------------------------------------------------------------------
[2022-12-27 20:49:19,609] {taskinstance.py:1357} INFO - Starting attempt 2 of 2
[2022-12-27 20:49:19,609] {taskinstance.py:1358} INFO - 
--------------------------------------------------------------------------------
[2022-12-27 20:49:19,620] {taskinstance.py:1377} INFO - Executing <Task(PythonOperator): transform_data> on 2022-12-27 20:42:14.349080+00:00
[2022-12-27 20:49:19,625] {standard_task_runner.py:52} INFO - Started process 7522 to run task
[2022-12-27 20:49:19,631] {standard_task_runner.py:79} INFO - Running: ['***', 'tasks', 'run', 'parking_pipeline', 'transform_data', 'scheduled__2022-12-27T20:42:14.349080+00:00', '--job-id', '285', '--raw', '--subdir', 'DAGS_FOLDER/parking_dag.py', '--cfg-path', '/tmp/tmp4aj8a1af', '--error-file', '/tmp/tmpd8xacufh']
[2022-12-27 20:49:19,632] {standard_task_runner.py:80} INFO - Job 285: Subtask transform_data
[2022-12-27 20:49:19,699] {task_command.py:369} INFO - Running <TaskInstance: parking_pipeline.transform_data scheduled__2022-12-27T20:42:14.349080+00:00 [running]> on host 8fbeee8d3d5a
[2022-12-27 20:49:19,775] {taskinstance.py:1571} INFO - Exporting the following env vars:
AIRFLOW_CTX_DAG_OWNER=Airflow
AIRFLOW_CTX_DAG_ID=parking_pipeline
AIRFLOW_CTX_TASK_ID=transform_data
AIRFLOW_CTX_EXECUTION_DATE=2022-12-27T20:42:14.349080+00:00
AIRFLOW_CTX_TRY_NUMBER=2
AIRFLOW_CTX_DAG_RUN_ID=scheduled__2022-12-27T20:42:14.349080+00:00
[2022-12-27 20:49:19,791] {taskinstance.py:1889} ERROR - Task failed with exception
Traceback (most recent call last):
  File "/home/airflow/.local/lib/python3.7/site-packages/airflow/operators/python.py", line 171, in execute
    return_value = self.execute_callable()
  File "/home/airflow/.local/lib/python3.7/site-packages/airflow/operators/python.py", line 189, in execute_callable
    return self.python_callable(*self.op_args, **self.op_kwargs)
  File "/opt/airflow/dags/parking_dag.py", line 35, in _transform_parking_data
    print(parking_data.keys())
AttributeError: 'list' object has no attribute 'keys'
[2022-12-27 20:49:19,805] {taskinstance.py:1400} INFO - Marking task as FAILED. dag_id=parking_pipeline, task_id=transform_data, execution_date=20221227T204214, start_date=20221227T204919, end_date=20221227T204919
[2022-12-27 20:49:19,812] {standard_task_runner.py:97} ERROR - Failed to execute job 285 for task transform_data ('list' object has no attribute 'keys'; 7522)
[2022-12-27 20:49:19,843] {local_task_job.py:156} INFO - Task exited with return code 1
[2022-12-27 20:49:19,880] {local_task_job.py:273} INFO - 0 downstream tasks scheduled from follow-on schedule check
